Workbook

Sheet Dashboard
B2: OSDD Search Tool - Performance & Efficiency Review
B3: Audit-log evidence, 30 Apr 2026 to 07 Aug 2026 | 5,294 logged runs | 69 analysts
B5: Comparison basis
B6: Baseline period | E6: Apr-Jun 2026
B7: Baseline rate (sec per search, weighted) | E7: =(SUMIFS(Data!$P$2:$P$5295,Data!$B$2:$B$5295,"2026-04")+SUMIFS(Data!$P$2:$P$5295,Data!$B$2:$B$5295,"2026-05")+SUMIFS(Data!$P$2:$P$5295,Data!$B$2:$B$5295,"2026-06"))/(SUMIFS(Data!$H$2:$H$5295,Data!$B$2:$B$5295,"2026-04")+SUMIFS(Data!$H$2:$H$5295,Data!$B$2:$B$5295,"2026-05")+SUMIFS(Data!$H$2:$H$5295,Data!$B$2:$B$5295,"2026-06"))
B8: Current rate (Jul-Aug 2026, sec per search, weighted) | E8: =(SUMIFS(Data!$P$2:$P$5295,Data!$B$2:$B$5295,"2026-07")+SUMIFS(Data!$P$2:$P$5295,Data!$B$2:$B$5295,"2026-08"))/(SUMIFS(Data!$H$2:$H$5295,Data!$B$2:$B$5295,"2026-07")+SUMIFS(Data!$H$2:$H$5295,Data!$B$2:$B$5295,"2026-08"))
B9: Searches run in the current period (Jul-Aug 2026) | E9: =(SUMIFS(Data!$H$2:$H$5295,Data!$B$2:$B$5295,"2026-07")+SUMIFS(Data!$H$2:$H$5295,Data!$B$2:$B$5295,"2026-08"))
B10: Marginal sec per search - baseline (least-squares fit) | E10: =SLOPE(INDEX(Data!$J$2:$J$5295,1):INDEX(Data!$J$2:$J$5295,MATCH("2026-07",Data!$B$2:$B$5295,0)-1),INDEX(Data!$H$2:$H$5295,1):INDEX(Data!$H$2:$H$5295,MATCH("2026-07",Data!$B$2:$B$5295,0)-1))
B11: Marginal sec per search - current (least-squares fit) | E11: =SLOPE(INDEX(Data!$J$2:$J$5295,MATCH("2026-07",Data!$B$2:$B$5295,0)):INDEX(Data!$J$2:$J$5295,5294),INDEX(Data!$H$2:$H$5295,MATCH("2026-07",Data!$B$2:$B$5295,0)):INDEX(Data!$H$2:$H$5295,5294))
B14: Efficiency gain per search | E14: Analyst hours avoided | H14: Runs finishing within 2 min | K14: Marginal sec per search, current | N14: Runs over 5 min, current
B15: =1-E8/E7 | E15: =E9*(E7-E8)/3600 | H15: ='Completion Curve'!C8 | K15: =E11 | N15: =SUMIFS(Data!$N$2:$N$5295,Data!$B$2:$B$5295,">=2026-07")/COUNTIFS(Data!$B$2:$B$5295,">=2026-07")
B16: Jul-Aug vs Apr-Jun, workload-adjusted | E16: Jul-Aug searches at the baseline rate vs the current rate | H16: current period; baseline comparison on the Completion Curve tab | K16: cost of each extra search; baseline value in E10 above | N16: monthly comparison in the chart below

Sheet Monthly Pivot
A1: OSDD Search Tool - Monthly Performance Pivot
A2: Source: audit log Sheet1 of the shared master tracker. One row = one tool run.
A4: Month | B4: Runs logged | C4: Active analysts | D4: Entities screened | E4: Searches run | F4: Avg entities / run | G4: Avg searches / run | H4: Median time / run (sec) | I4: Avg time / run (sec) | J4: Avg time / run (min) | K4: P90 time / run (sec) | L4: Sec per search (weighted) | M4: Sec per entity (weighted) | N4: Fixed overhead / run (sec) | O4: Marginal sec per search | P4: Fit quality (R2) | Q4: Runs over 5 min | R4: Runs over 10 min | S4: Total tool hours | U4: Chart label
A5: 2026-04 | B5: =COUNTIFS(Data!$B$2:$B$5295,$A5) | C5: =Helper!B72 | D5: =SUMIFS(Data!$G$2:$G$5295,Data!$B$2:$B$5295,$A5) | E5: =SUMIFS(Data!$H$2:$H$5295,Data!$B$2:$B$5295,$A5) | F5: =IFERROR(D5/B5,"") | G5: =IFERROR(E5/B5,"") | H5: =MEDIAN(INDEX(Data!$J$2:$J$5295,MATCH($A5,Data!$B$2:$B$5295,0)):INDEX(Data!$J$2:$J$5295,MATCH($A5,Data!$B$2:$B$5295,0)+COUNTIFS(Data!$B$2:$B$5295,$A5)-1)) | I5: =AVERAGEIFS(Data!$J$2:$J$5295,Data!$B$2:$B$5295,$A5) | J5: =I5/60 | K5: =PERCENTILE(INDEX(Data!$J$2:$J$5295,MATCH($A5,Data!$B$2:$B$5295,0)):INDEX(Data!$J$2:$J$5295,MATCH($A5,Data!$B$2:$B$5295,0)+COUNTIFS(Data!$B$2:$B$5295,$A5)-1),0.9) | L5: =IFERROR(SUMIFS(Data!$P$2:$P$5295,Data!$B$2:$B$5295,$A5)/E5,"") | M5: =IFERROR(SUMIFS(Data!$J$2:$J$5295,Data!$B$2:$B$5295,$A5)/D5,"") | N5: =INTERCEPT(INDEX(Data!$J$2:$J$5295,MATCH($A5,Data!$B$2:$B$5295,0)):INDEX(Data!$J$2:$J$5295,MATCH($A5,Data!$B$2:$B$5295,0)+COUNTIFS(Data!$B$2:$B$5295,$A5)-1),INDEX(Data!$H$2:$H$5295,MATCH($A5,Data!$B$2:$B$5295,0)):INDEX(Data!$H$2:$H$5295,MATCH($A5,Data!$B$2:$B$5295,0)+COUNTIFS(Data!$B$2:$B$5295,$A5)-1)) | O5: =SLOPE(INDEX(Data!$J$2:$J$5295,MATCH($A5,Data!$B$2:$B$5295,0)):INDEX(Data!$J$2:$J$5295,MATCH($A5,Data!$B$2:$B$5295,0)+COUNTIFS(Data!$B$2:$B$5295,$A5)-1),INDEX(Data!$H$2:$H$5295,MATCH($A5,Data!$B$2:$B$5295,0)):INDEX(Data!$H$2:$H$5295,MATCH($A5,Data!$B$2:$B$5295,0)+COUNTIFS(Data!$B$2:$B$5295,$A5)-1)) | P5: =RSQ(INDEX(Data!$J$2:$J$5295,MATCH($A5,Data!$B$2:$B$5295,0)):INDEX(Data!$J$2:$J$5295,MATCH($A5,Data!$B$2:$B$5295,0)+COUNTIFS(Data!$B$2:$B$5295,$A5)-1),INDEX(Data!$H$2:$H$5295,MATCH($A5,Data!$B$2:$B$5295,0)):INDEX(Data!$H$2:$H$5295,MATCH($A5,Data!$B$2:$B$5295,0)+COUNTIFS(Data!$B$2:$B$5295,$A5)-1)) | Q5: =IFERROR(SUMIFS(Data!$N$2:$N$5295,Data!$B$2:$B$5295,$A5)/B5,"") | R5: =IFERROR(SUMIFS(Data!$O$2:$O$5295,Data!$B$2:$B$5295,$A5)/B5,"") | S5: =SUMIFS(Data!$J$2:$J$5295,Data!$B$2:$B$5295,$A5)/3600 | U5: =TEXT(DATEVALUE($A5&"-01"),"MMM-YY")&" (n="&TEXT(B5,"#,##0")&")"
A6: 2026-05 | B6: =COUNTIFS(Data!$B$2:$B$5295,$A6) | C6: =Helper!C72 | D6: =SUMIFS(Data!$G$2:$G$5295,Data!$B$2:$B$5295,$A6) | E6: =SUMIFS(Data!$H$2:$H$5295,Data!$B$2:$B$5295,$A6) | F6: =IFERROR(D6/B6,"") | G6: =IFERROR(E6/B6,"") | H6: =MEDIAN(INDEX(Data!$J$2:$J$5295,MATCH($A6,Data!$B$2:$B$5295,0)):INDEX(Data!$J$2:$J$5295,MATCH($A6,Data!$B$2:$B$5295,0)+COUNTIFS(Data!$B$2:$B$5295,$A6)-1)) | I6: =AVERAGEIFS(Data!$J$2:$J$5295,Data!$B$2:$B$5295,$A6) | J6: =I6/60 | K6: =PERCENTILE(INDEX(Data!$J$2:$J$5295,MATCH($A6,Data!$B$2:$B$5295,0)):INDEX(Data!$J$2:$J$5295,MATCH($A6,Data!$B$2:$B$5295,0)+COUNTIFS(Data!$B$2:$B$5295,$A6)-1),0.9) | L6: =IFERROR(SUMIFS(Data!$P$2:$P$5295,Data!$B$2:$B$5295,$A6)/E6,"") | M6: =IFERROR(SUMIFS(Data!$J$2:$J$5295,Data!$B$2:$B$5295,$A6)/D6,"") | N6: =INTERCEPT(INDEX(Data!$J$2:$J$5295,MATCH($A6,Data!$B$2:$B$5295,0)):INDEX(Data!$J$2:$J$5295,MATCH($A6,Data!$B$2:$B$5295,0)+COUNTIFS(Data!$B$2:$B$5295,$A6)-1),INDEX(Data!$H$2:$H$5295,MATCH($A6,Data!$B$2:$B$5295,0)):INDEX(Data!$H$2:$H$5295,MATCH($A6,Data!$B$2:$B$5295,0)+COUNTIFS(Data!$B$2:$B$5295,$A6)-1)) | O6: =SLOPE(INDEX(Data!$J$2:$J$5295,MATCH($A6,Data!$B$2:$B$5295,0)):INDEX(Data!$J$2:$J$5295,MATCH($A6,Data!$B$2:$B$5295,0)+COUNTIFS(Data!$B$2:$B$5295,$A6)-1),INDEX(Data!$H$2:$H$5295,MATCH($A6,Data!$B$2:$B$5295,0)):INDEX(Data!$H$2:$H$5295,MATCH($A6,Data!$B$2:$B$5295,0)+COUNTIFS(Data!$B$2:$B$5295,$A6)-1)) | P6: =RSQ(INDEX(Data!$J$2:$J$5295,MATCH($A6,Data!$B$2:$B$5295,0)):INDEX(Data!$J$2:$J$5295,MATCH($A6,Data!$B$2:$B$5295,0)+COUNTIFS(Data!$B$2:$B$5295,$A6)-1),INDEX(Data!$H$2:$H$5295,MATCH($A6,Data!$B$2:$B$5295,0)):INDEX(Data!$H$2:$H$5295,MATCH($A6,Data!$B$2:$B$5295,0)+COUNTIFS(Data!$B$2:$B$5295,$A6)-1)) | Q6: =IFERROR(SUMIFS(Data!$N$2:$N$5295,Data!$B$2:$B$5295,$A6)/B6,"") | R6: =IFERROR(SUMIFS(Data!$O$2:$O$5295,Data!$B$2:$B$5295,$A6)/B6,"") | S6: =SUMIFS(Data!$J$2:$J$5295,Data!$B$2:$B$5295,$A6)/3600 | U6: =TEXT(DATEVALUE($A6&"-01"),"MMM-YY")&" (n="&TEXT(B6,"#,##0")&")"
A7: 2026-06 | B7: =COUNTIFS(Data!$B$2:$B$5295,$A7) | C7: =Helper!D72 | D7: =SUMIFS(Data!$G$2:$G$5295,Data!$B$2:$B$5295,$A7) | E7: =SUMIFS(Data!$H$2:$H$5295,Data!$B$2:$B$5295,$A7) | F7: =IFERROR(D7/B7,"") | G7: =IFERROR(E7/B7,"") | H7: =MEDIAN(INDEX(Data!$J$2:$J$5295,MATCH($A7,Data!$B$2:$B$5295,0)):INDEX(Data!$J$2:$J$5295,MATCH($A7,Data!$B$2:$B$5295,0)+COUNTIFS(Data!$B$2:$B$5295,$A7)-1)) | I7: =AVERAGEIFS(Data!$J$2:$J$5295,Data!$B$2:$B$5295,$A7) | J7: =I7/60 | K7: =PERCENTILE(INDEX(Data!$J$2:$J$5295,MATCH($A7,Data!$B$2:$B$5295,0)):INDEX(Data!$J$2:$J$5295,MATCH($A7,Data!$B$2:$B$5295,0)+COUNTIFS(Data!$B$2:$B$5295,$A7)-1),0.9) | L7: =IFERROR(SUMIFS(Data!$P$2:$P$5295,Data!$B$2:$B$5295,$A7)/E7,"") | M7: =IFERROR(SUMIFS(Data!$J$2:$J$5295,Data!$B$2:$B$5295,$A7)/D7,"") | N7: =INTERCEPT(INDEX(Data!$J$2:$J$5295,MATCH($A7,Data!$B$2:$B$5295,0)):INDEX(Data!$J$2:$J$5295,MATCH($A7,Data!$B$2:$B$5295,0)+COUNTIFS(Data!$B$2:$B$5295,$A7)-1),INDEX(Data!$H$2:$H$5295,MATCH($A7,Data!$B$2:$B$5295,0)):INDEX(Data!$H$2:$H$5295,MATCH($A7,Data!$B$2:$B$5295,0)+COUNTIFS(Data!$B$2:$B$5295,$A7)-1)) | O7: =SLOPE(INDEX(Data!$J$2:$J$5295,MATCH($A7,Data!$B$2:$B$5295,0)):INDEX(Data!$J$2:$J$5295,MATCH($A7,Data!$B$2:$B$5295,0)+COUNTIFS(Data!$B$2:$B$5295,$A7)-1),INDEX(Data!$H$2:$H$5295,MATCH($A7,Data!$B$2:$B$5295,0)):INDEX(Data!$H$2:$H$5295,MATCH($A7,Data!$B$2:$B$5295,0)+COUNTIFS(Data!$B$2:$B$5295,$A7)-1)) | P7: =RSQ(INDEX(Data!$J$2:$J$5295,MATCH($A7,Data!$B$2:$B$5295,0)):INDEX(Data!$J$2:$J$5295,MATCH($A7,Data!$B$2:$B$5295,0)+COUNTIFS(Data!$B$2:$B$5295,$A7)-1),INDEX(Data!$H$2:$H$5295,MATCH($A7,Data!$B$2:$B$5295,0)):INDEX(Data!$H$2:$H$5295,MATCH($A7,Data!$B$2:$B$5295,0)+COUNTIFS(Data!$B$2:$B$5295,$A7)-1)) | Q7: =IFERROR(SUMIFS(Data!$N$2:$N$5295,Data!$B$2:$B$5295,$A7)/B7,"") | R7: =IFERROR(SUMIFS(Data!$O$2:$O$5295,Data!$B$2:$B$5295,$A7)/B7,"") | S7: =SUMIFS(Data!$J$2:$J$5295,Data!$B$2:$B$5295,$A7)/3600 | U7: =TEXT(DATEVALUE($A7&"-01"),"MMM-YY")&" (n="&TEXT(B7,"#,##0")&")"
A8: 2026-07 | B8: =COUNTIFS(Data!$B$2:$B$5295,$A8) | C8: =Helper!E72 | D8: =SUMIFS(Data!$G$2:$G$5295,Data!$B$2:$B$5295,$A8) | E8: =SUMIFS(Data!$H$2:$H$5295,Data!$B$2:$B$5295,$A8) | F8: =IFERROR(D8/B8,"") | G8: =IFERROR(E8/B8,"") | H8: =MEDIAN(INDEX(Data!$J$2:$J$5295,MATCH($A8,Data!$B$2:$B$5295,0)):INDEX(Data!$J$2:$J$5295,MATCH($A8,Data!$B$2:$B$5295,0)+COUNTIFS(Data!$B$2:$B$5295,$A8)-1)) | I8: =AVERAGEIFS(Data!$J$2:$J$5295,Data!$B$2:$B$5295,$A8) | J8: =I8/60 | K8: =PERCENTILE(INDEX(Data!$J$2:$J$5295,MATCH($A8,Data!$B$2:$B$5295,0)):INDEX(Data!$J$2:$J$5295,MATCH($A8,Data!$B$2:$B$5295,0)+COUNTIFS(Data!$B$2:$B$5295,$A8)-1),0.9) | L8: =IFERROR(SUMIFS(Data!$P$2:$P$5295,Data!$B$2:$B$5295,$A8)/E8,"") | M8: =IFERROR(SUMIFS(Data!$J$2:$J$5295,Data!$B$2:$B$5295,$A8)/D8,"") | N8: =INTERCEPT(INDEX(Data!$J$2:$J$5295,MATCH($A8,Data!$B$2:$B$5295,0)):INDEX(Data!$J$2:$J$5295,MATCH($A8,Data!$B$2:$B$5295,0)+COUNTIFS(Data!$B$2:$B$5295,$A8)-1),INDEX(Data!$H$2:$H$5295,MATCH($A8,Data!$B$2:$B$5295,0)):INDEX(Data!$H$2:$H$5295,MATCH($A8,Data!$B$2:$B$5295,0)+COUNTIFS(Data!$B$2:$B$5295,$A8)-1)) | O8: =SLOPE(INDEX(Data!$J$2:$J$5295,MATCH($A8,Data!$B$2:$B$5295,0)):INDEX(Data!$J$2:$J$5295,MATCH($A8,Data!$B$2:$B$5295,0)+COUNTIFS(Data!$B$2:$B$5295,$A8)-1),INDEX(Data!$H$2:$H$5295,MATCH($A8,Data!$B$2:$B$5295,0)):INDEX(Data!$H$2:$H$5295,MATCH($A8,Data!$B$2:$B$5295,0)+COUNTIFS(Data!$B$2:$B$5295,$A8)-1)) | P8: =RSQ(INDEX(Data!$J$2:$J$5295,MATCH($A8,Data!$B$2:$B$5295,0)):INDEX(Data!$J$2:$J$5295,MATCH($A8,Data!$B$2:$B$5295,0)+COUNTIFS(Data!$B$2:$B$5295,$A8)-1),INDEX(Data!$H$2:$H$5295,MATCH($A8,Data!$B$2:$B$5295,0)):INDEX(Data!$H$2:$H$5295,MATCH($A8,Data!$B$2:$B$5295,0)+COUNTIFS(Data!$B$2:$B$5295,$A8)-1)) | Q8: =IFERROR(SUMIFS(Data!$N$2:$N$5295,Data!$B$2:$B$5295,$A8)/B8,"") | R8: =IFERROR(SUMIFS(Data!$O$2:$O$5295,Data!$B$2:$B$5295,$A8)/B8,"") | S8: =SUMIFS(Data!$J$2:$J$5295,Data!$B$2:$B$5295,$A8)/3600 | U8: =TEXT(DATEVALUE($A8&"-01"),"MMM-YY")&" (n="&TEXT(B8,"#,##0")&")"
A9: 2026-08 | B9: =COUNTIFS(Data!$B$2:$B$5295,$A9) | C9: =Helper!F72 | D9: =SUMIFS(Data!$G$2:$G$5295,Data!$B$2:$B$5295,$A9) | E9: =SUMIFS(Data!$H$2:$H$5295,Data!$B$2:$B$5295,$A9) | F9: =IFERROR(D9/B9,"") | G9: =IFERROR(E9/B9,"") | H9: =MEDIAN(INDEX(Data!$J$2:$J$5295,MATCH($A9,Data!$B$2:$B$5295,0)):INDEX(Data!$J$2:$J$5295,MATCH($A9,Data!$B$2:$B$5295,0)+COUNTIFS(Data!$B$2:$B$5295,$A9)-1)) | I9: =AVERAGEIFS(Data!$J$2:$J$5295,Data!$B$2:$B$5295,$A9) | J9: =I9/60 | K9: =PERCENTILE(INDEX(Data!$J$2:$J$5295,MATCH($A9,Data!$B$2:$B$5295,0)):INDEX(Data!$J$2:$J$5295,MATCH($A9,Data!$B$2:$B$5295,0)+COUNTIFS(Data!$B$2:$B$5295,$A9)-1),0.9) | L9: =IFERROR(SUMIFS(Data!$P$2:$P$5295,Data!$B$2:$B$5295,$A9)/E9,"") | M9: =IFERROR(SUMIFS(Data!$J$2:$J$5295,Data!$B$2:$B$5295,$A9)/D9,"") | N9: =INTERCEPT(INDEX(Data!$J$2:$J$5295,MATCH($A9,Data!$B$2:$B$5295,0)):INDEX(Data!$J$2:$J$5295,MATCH($A9,Data!$B$2:$B$5295,0)+COUNTIFS(Data!$B$2:$B$5295,$A9)-1),INDEX(Data!$H$2:$H$5295,MATCH($A9,Data!$B$2:$B$5295,0)):INDEX(Data!$H$2:$H$5295,MATCH($A9,Data!$B$2:$B$5295,0)+COUNTIFS(Data!$B$2:$B$5295,$A9)-1)) | O9: =SLOPE(INDEX(Data!$J$2:$J$5295,MATCH($A9,Data!$B$2:$B$5295,0)):INDEX(Data!$J$2:$J$5295,MATCH($A9,Data!$B$2:$B$5295,0)+COUNTIFS(Data!$B$2:$B$5295,$A9)-1),INDEX(Data!$H$2:$H$5295,MATCH($A9,Data!$B$2:$B$5295,0)):INDEX(Data!$H$2:$H$5295,MATCH($A9,Data!$B$2:$B$5295,0)+COUNTIFS(Data!$B$2:$B$5295,$A9)-1)) | P9: =RSQ(INDEX(Data!$J$2:$J$5295,MATCH($A9,Data!$B$2:$B$5295,0)):INDEX(Data!$J$2:$J$5295,MATCH($A9,Data!$B$2:$B$5295,0)+COUNTIFS(Data!$B$2:$B$5295,$A9)-1),INDEX(Data!$H$2:$H$5295,MATCH($A9,Data!$B$2:$B$5295,0)):INDEX(Data!$H$2:$H$5295,MATCH($A9,Data!$B$2:$B$5295,0)+COUNTIFS(Data!$B$2:$B$5295,$A9)-1)) | Q9: =IFERROR(SUMIFS(Data!$N$2:$N$5295,Data!$B$2:$B$5295,$A9)/B9,"") | R9: =IFERROR(SUMIFS(Data!$O$2:$O$5295,Data!$B$2:$B$5295,$A9)/B9,"") | S9: =SUMIFS(Data!$J$2:$J$5295,Data!$B$2:$B$5295,$A9)/3600 | U9: =TEXT(DATEVALUE($A9&"-01"),"MMM-YY")&" (n="&TEXT(B9,"#,##0")&")"
A10: All months | B10: =SUM(B5:B9) | C10: =COUNTIF(Helper!$A$2:$A$70,"<>") | D10: =SUM(D5:D9) | E10: =SUM(E5:E9) | F10: =D10/B10 | G10: =E10/B10 | H10: =MEDIAN(Data!$J$2:$J$5295) | I10: =AVERAGE(Data!$J$2:$J$5295) | J10: =I10/60 | K10: =PERCENTILE(Data!$J$2:$J$5295,0.9) | L10: =SUM(Data!$P$2:$P$5295)/E10 | M10: =SUM(Data!$J$2:$J$5295)/D10 | N10: =INTERCEPT(Data!$J$2:$J$5295,Data!$H$2:$H$5295) | O10: =SLOPE(Data!$J$2:$J$5295,Data!$H$2:$H$5295) | P10: =RSQ(Data!$J$2:$J$5295,Data!$H$2:$H$5295) | Q10: =SUM(Data!$N$2:$N$5295)/B10 | R10: =SUM(Data!$O$2:$O$5295)/B10 | S10: =SUM(S5:S9)
A12: Definitions
A13: - Median / average / P90 time per run are the same measure at three points of the distribution, shown smallest to largest. P90 means 9 runs in 10 finished faster than this value.
A14: - Sec per search (weighted) = total run seconds / total searches. Sec per entity (weighted) = total run seconds / total entities. Both normalise for the fact that case size changed over the period.
A15: - Fixed overhead / run and Marginal sec per search come from a least-squares fit of run duration against the number of searches in that run (INTERCEPT and SLOPE). Fixed overhead is the part of a run that does not depend on search count - launch, sign-in, file handling. Marginal sec per search is the cost of each additional search.
A16: - Fit quality (R2) is how much of the variation in run duration the search count explains. Values near 1 mean run time is almost entirely driven by search volume.
A17: - Runs over 5 / 10 min = share of that month's runs exceeding those durations.
A18: - Apr-2026 covers two days and 22 runs; sample sizes are shown in the chart labels so small months are not read as trend.
A19: - Aug-2026 covers 01-07 Aug 2026 only; monthly volumes for that month are partial.
A20: - 96 source rows logged a timestamp but no run detail and are excluded (see Notes & Method).

Sheet Completion Curve
A1: How long an analyst waits for a run to finish
A2: Cumulative share of runs completing within each duration. Baseline = Apr-Jun 2026, Current = Jul-Aug 2026.
A4: Completed within | B4: Baseline Apr-Jun | C4: Current Jul-Aug | D4: Change (pp)
A5: 30 sec | B5: =COUNTIFS(Data!$J$2:$J$5295,"<="&30,Data!$B$2:$B$5295,"<=2026-06")/COUNTIFS(Data!$B$2:$B$5295,"<=2026-06") | C5: =COUNTIFS(Data!$J$2:$J$5295,"<="&30,Data!$B$2:$B$5295,">=2026-07")/COUNTIFS(Data!$B$2:$B$5295,">=2026-07") | D5: =C5-B5
A6: 1 min | B6: =COUNTIFS(Data!$J$2:$J$5295,"<="&60,Data!$B$2:$B$5295,"<=2026-06")/COUNTIFS(Data!$B$2:$B$5295,"<=2026-06") | C6: =COUNTIFS(Data!$J$2:$J$5295,"<="&60,Data!$B$2:$B$5295,">=2026-07")/COUNTIFS(Data!$B$2:$B$5295,">=2026-07") | D6: =C6-B6
A7: 1.5 min | B7: =COUNTIFS(Data!$J$2:$J$5295,"<="&90,Data!$B$2:$B$5295,"<=2026-06")/COUNTIFS(Data!$B$2:$B$5295,"<=2026-06") | C7: =COUNTIFS(Data!$J$2:$J$5295,"<="&90,Data!$B$2:$B$5295,">=2026-07")/COUNTIFS(Data!$B$2:$B$5295,">=2026-07") | D7: =C7-B7
A8: 2 min | B8: =COUNTIFS(Data!$J$2:$J$5295,"<="&120,Data!$B$2:$B$5295,"<=2026-06")/COUNTIFS(Data!$B$2:$B$5295,"<=2026-06") | C8: =COUNTIFS(Data!$J$2:$J$5295,"<="&120,Data!$B$2:$B$5295,">=2026-07")/COUNTIFS(Data!$B$2:$B$5295,">=2026-07") | D8: =C8-B8
A9: 3 min | B9: =COUNTIFS(Data!$J$2:$J$5295,"<="&180,Data!$B$2:$B$5295,"<=2026-06")/COUNTIFS(Data!$B$2:$B$5295,"<=2026-06") | C9: =COUNTIFS(Data!$J$2:$J$5295,"<="&180,Data!$B$2:$B$5295,">=2026-07")/COUNTIFS(Data!$B$2:$B$5295,">=2026-07") | D9: =C9-B9
A10: 4 min | B10: =COUNTIFS(Data!$J$2:$J$5295,"<="&240,Data!$B$2:$B$5295,"<=2026-06")/COUNTIFS(Data!$B$2:$B$5295,"<=2026-06") | C10: =COUNTIFS(Data!$J$2:$J$5295,"<="&240,Data!$B$2:$B$5295,">=2026-07")/COUNTIFS(Data!$B$2:$B$5295,">=2026-07") | D10: =C10-B10
A11: 5 min | B11: =COUNTIFS(Data!$J$2:$J$5295,"<="&300,Data!$B$2:$B$5295,"<=2026-06")/COUNTIFS(Data!$B$2:$B$5295,"<=2026-06") | C11: =COUNTIFS(Data!$J$2:$J$5295,"<="&300,Data!$B$2:$B$5295,">=2026-07")/COUNTIFS(Data!$B$2:$B$5295,">=2026-07") | D11: =C11-B11
A12: 10 min | B12: =COUNTIFS(Data!$J$2:$J$5295,"<="&600,Data!$B$2:$B$5295,"<=2026-06")/COUNTIFS(Data!$B$2:$B$5295,"<=2026-06") | C12: =COUNTIFS(Data!$J$2:$J$5295,"<="&600,Data!$B$2:$B$5295,">=2026-07")/COUNTIFS(Data!$B$2:$B$5295,">=2026-07") | D12: =C12-B12
A13: 15 min | B13: =COUNTIFS(Data!$J$2:$J$5295,"<="&900,Data!$B$2:$B$5295,"<=2026-06")/COUNTIFS(Data!$B$2:$B$5295,"<=2026-06") | C13: =COUNTIFS(Data!$J$2:$J$5295,"<="&900,Data!$B$2:$B$5295,">=2026-07")/COUNTIFS(Data!$B$2:$B$5295,">=2026-07") | D13: =C13-B13

Sheet Weekly Trend
A1: Week-by-week volume and efficiency
A3: Week starting | B3: Runs | C3: Searches | D3: Sec per search (weighted) | E3: Avg time / run (sec)
A4: 46139 | B4: =COUNTIFS(Data!$D$2:$D$5295,$A4) | C4: =SUMIFS(Data!$H$2:$H$5295,Data!$D$2:$D$5295,$A4) | D4: =IFERROR(SUMIFS(Data!$P$2:$P$5295,Data!$D$2:$D$5295,$A4)/C4,"") | E4: =IFERROR(AVERAGEIFS(Data!$J$2:$J$5295,Data!$D$2:$D$5295,$A4),"")
A5: 46146 | B5: =COUNTIFS(Data!$D$2:$D$5295,$A5) | C5: =SUMIFS(Data!$H$2:$H$5295,Data!$D$2:$D$5295,$A5) | D5: =IFERROR(SUMIFS(Data!$P$2:$P$5295,Data!$D$2:$D$5295,$A5)/C5,"") | E5: =IFERROR(AVERAGEIFS(Data!$J$2:$J$5295,Data!$D$2:$D$5295,$A5),"")
A6: 46153 | B6: =COUNTIFS(Data!$D$2:$D$5295,$A6) | C6: =SUMIFS(Data!$H$2:$H$5295,Data!$D$2:$D$5295,$A6) | D6: =IFERROR(SUMIFS(Data!$P$2:$P$5295,Data!$D$2:$D$5295,$A6)/C6,"") | E6: =IFERROR(AVERAGEIFS(Data!$J$2:$J$5295,Data!$D$2:$D$5295,$A6),"")
A7: 46160 | B7: =COUNTIFS(Data!$D$2:$D$5295,$A7) | C7: =SUMIFS(Data!$H$2:$H$5295,Data!$D$2:$D$5295,$A7) | D7: =IFERROR(SUMIFS(Data!$P$2:$P$5295,Data!$D$2:$D$5295,$A7)/C7,"") | E7: =IFERROR(AVERAGEIFS(Data!$J$2:$J$5295,Data!$D$2:$D$5295,$A7),"")
A8: 46167 | B8: =COUNTIFS(Data!$D$2:$D$5295,$A8) | C8: =SUMIFS(Data!$H$2:$H$5295,Data!$D$2:$D$5295,$A8) | D8: =IFERROR(SUMIFS(Data!$P$2:$P$5295,Data!$D$2:$D$5295,$A8)/C8,"") | E8: =IFERROR(AVERAGEIFS(Data!$J$2:$J$5295,Data!$D$2:$D$5295,$A8),"")
A9: 46174 | B9: =COUNTIFS(Data!$D$2:$D$5295,$A9) | C9: =SUMIFS(Data!$H$2:$H$5295,Data!$D$2:$D$5295,$A9) | D9: =IFERROR(SUMIFS(Data!$P$2:$P$5295,Data!$D$2:$D$5295,$A9)/C9,"") | E9: =IFERROR(AVERAGEIFS(Data!$J$2:$J$5295,Data!$D$2:$D$5295,$A9),"")
A10: 46181 | B10: =COUNTIFS(Data!$D$2:$D$5295,$A10) | C10: =SUMIFS(Data!$H$2:$H$5295,Data!$D$2:$D$5295,$A10) | D10: =IFERROR(SUMIFS(Data!$P$2:$P$5295,Data!$D$2:$D$5295,$A10)/C10,"") | E10: =IFERROR(AVERAGEIFS(Data!$J$2:$J$5295,Data!$D$2:$D$5295,$A10),"")
A11: 46188 | B11: =COUNTIFS(Data!$D$2:$D$5295,$A11) | C11: =SUMIFS(Data!$H$2:$H$5295,Data!$D$2:$D$5295,$A11) | D11: =IFERROR(SUMIFS(Data!$P$2:$P$5295,Data!$D$2:$D$5295,$A11)/C11,"") | E11: =IFERROR(AVERAGEIFS(Data!$J$2:$J$5295,Data!$D$2:$D$5295,$A11),"")
A12: 46195 | B12: =COUNTIFS(Data!$D$2:$D$5295,$A12) | C12: =SUMIFS(Data!$H$2:$H$5295,Data!$D$2:$D$5295,$A12) | D12: =IFERROR(SUMIFS(Data!$P$2:$P$5295,Data!$D$2:$D$5295,$A12)/C12,"") | E12: =IFERROR(AVERAGEIFS(Data!$J$2:$J$5295,Data!$D$2:$D$5295,$A12),"")
A13: 46202 | B13: =COUNTIFS(Data!$D$2:$D$5295,$A13) | C13: =SUMIFS(Data!$H$2:$H$5295,Data!$D$2:$D$5295,$A13) | D13: =IFERROR(SUMIFS(Data!$P$2:$P$5295,Data!$D$2:$D$5295,$A13)/C13,"") | E13: =IFERROR(AVERAGEIFS(Data!$J$2:$J$5295,Data!$D$2:$D$5295,$A13),"")
A14: 46209 | B14: =COUNTIFS(Data!$D$2:$D$5295,$A14) | C14: =SUMIFS(Data!$H$2:$H$5295,Data!$D$2:$D$5295,$A14) | D14: =IFERROR(SUMIFS(Data!$P$2:$P$5295,Data!$D$2:$D$5295,$A14)/C14,"") | E14: =IFERROR(AVERAGEIFS(Data!$J$2:$J$5295,Data!$D$2:$D$5295,$A14),"")
A15: 46216 | B15: =COUNTIFS(Data!$D$2:$D$5295,$A15) | C15: =SUMIFS(Data!$H$2:$H$5295,Data!$D$2:$D$5295,$A15) | D15: =IFERROR(SUMIFS(Data!$P$2:$P$5295,Data!$D$2:$D$5295,$A15)/C15,"") | E15: =IFERROR(AVERAGEIFS(Data!$J$2:$J$5295,Data!$D$2:$D$5295,$A15),"")
... A18: 46237 | B18: =COUNTIFS(Data!$D$2:$D$5295,$A18) | C18: =SUMIFS(Data!$H$2:$H$5295,Data!$D$2:$D$5295,$A18) | D18: =IFERROR(SUMIFS(Data!$P$2:$P$5295,Data!$D$2:$D$5295,$A18)/C18,"") | E18: =IFERROR(AVERAGEIFS(Data!$J$2:$J$5295,Data!$D$2:$D$5295,$A18),"")

Sheet Release Impact
A1: Performance by tool version
A3: Tool version | B3: First logged | C3: Last logged | D3: Runs | E3: Searches | F3: Avg searches / run | G3: Sec per search (weighted) | H3: Avg time / run (sec) | I3: Runs over 5 min
A4: 2.4.1 | B4: 46142.09 | C4: 46143.018 | D4: =COUNTIFS(Data!$M$2:$M$5295,$A4) | E4: =SUMIFS(Data!$H$2:$H$5295,Data!$M$2:$M$5295,$A4) | F4: =IFERROR(E4/D4,"") | G4: =IFERROR(SUMIFS(Data!$P$2:$P$5295,Data!$M$2:$M$5295,$A4)/E4,"") | H4: =IFERROR(AVERAGEIFS(Data!$J$2:$J$5295,Data!$M$2:$M$5295,$A4),"") | I4: =IFERROR(SUMIFS(Data!$N$2:$N$5295,Data!$M$2:$M$5295,$A4)/D4,"")
A5: 2.5.12 | B5: 46146.113 | C5: 46240.561 | D5: =COUNTIFS(Data!$M$2:$M$5295,$A5) | E5: =SUMIFS(Data!$H$2:$H$5295,Data!$M$2:$M$5295,$A5) | F5: =IFERROR(E5/D5,"") | G5: =IFERROR(SUMIFS(Data!$P$2:$P$5295,Data!$M$2:$M$5295,$A5)/E5,"") | H5: =IFERROR(AVERAGEIFS(Data!$J$2:$J$5295,Data!$M$2:$M$5295,$A5),"") | I5: =IFERROR(SUMIFS(Data!$N$2:$N$5295,Data!$M$2:$M$5295,$A5)/D5,"")
A6: 2.5.9 | B6: 46146.317 | C6: 46146.317 | D6: =COUNTIFS(Data!$M$2:$M$5295,$A6) | E6: =SUMIFS(Data!$H$2:$H$5295,Data!$M$2:$M$5295,$A6) | F6: =IFERROR(E6/D6,"") | G6: =IFERROR(SUMIFS(Data!$P$2:$P$5295,Data!$M$2:$M$5295,$A6)/E6,"") | H6: =IFERROR(AVERAGEIFS(Data!$J$2:$J$5295,Data!$M$2:$M$5295,$A6),"") | I6: =IFERROR(SUMIFS(Data!$N$2:$N$5295,Data!$M$2:$M$5295,$A6)/D6,"")
A7: 2.5.10 | B7: 46146.329 | C7: 46146.329 | D7: =COUNTIFS(Data!$M$2:$M$5295,$A7) | E7: =SUMIFS(Data!$H$2:$H$5295,Data!$M$2:$M$5295,$A7) | F7: =IFERROR(E7/D7,"") | G7: =IFERROR(SUMIFS(Data!$P$2:$P$5295,Data!$M$2:$M$5295,$A7)/E7,"") | H7: =IFERROR(AVERAGEIFS(Data!$J$2:$J$5295,Data!$M$2:$M$5295,$A7),"") | I7: =IFERROR(SUMIFS(Data!$N$2:$N$5295,Data!$M$2:$M$5295,$A7)/D7,"")
A8: 2.5.11 | B8: 46146.347 | C8: 46146.347 | D8: =COUNTIFS(Data!$M$2:$M$5295,$A8) | E8: =SUMIFS(Data!$H$2:$H$5295,Data!$M$2:$M$5295,$A8) | F8: =IFERROR(E8/D8,"") | G8: =IFERROR(SUMIFS(Data!$P$2:$P$5295,Data!$M$2:$M$5295,$A8)/E8,"") | H8: =IFERROR(AVERAGEIFS(Data!$J$2:$J$5295,Data!$M$2:$M$5295,$A8),"") | I8: =IFERROR(SUMIFS(Data!$N$2:$N$5295,Data!$M$2:$M$5295,$A8)/D8,"")
A9: 2.6.0 | B9: 46230.377 | C9: 46230.739 | D9: =COUNTIFS(Data!$M$2:$M$5295,$A9) | E9: =SUMIFS(Data!$H$2:$H$5295,Data!$M$2:$M$5295,$A9) | F9: =IFERROR(E9/D9,"") | G9: =IFERROR(SUMIFS(Data!$P$2:$P$5295,Data!$M$2:$M$5295,$A9)/E9,"") | H9: =IFERROR(AVERAGEIFS(Data!$J$2:$J$5295,Data!$M$2:$M$5295,$A9),"") | I9: =IFERROR(SUMIFS(Data!$N$2:$N$5295,Data!$M$2:$M$5295,$A9)/D9,"")
A10: 3.4 | B10: 46230.764 | C10: 46240.711 | D10: =COUNTIFS(Data!$M$2:$M$5295,$A10) | E10: =SUMIFS(Data!$H$2:$H$5295,Data!$M$2:$M$5295,$A10) | F10: =IFERROR(E10/D10,"") | G10: =IFERROR(SUMIFS(Data!$P$2:$P$5295,Data!$M$2:$M$5295,$A10)/E10,"") | H10: =IFERROR(AVERAGEIFS(Data!$J$2:$J$5295,Data!$M$2:$M$5295,$A10),"") | I10: =IFERROR(SUMIFS(Data!$N$2:$N$5295,Data!$M$2:$M$5295,$A10)/D10,"")
A11: 3.5 | B11: 46233.469 | C11: 46241.527 | D11: =COUNTIFS(Data!$M$2:$M$5295,$A11) | E11: =SUMIFS(Data!$H$2:$H$5295,Data!$M$2:$M$5295,$A11) | F11: =IFERROR(E11/D11,"") | G11: =IFERROR(SUMIFS(Data!$P$2:$P$5295,Data!$M$2:$M$5295,$A11)/E11,"") | H11: =IFERROR(AVERAGEIFS(Data!$J$2:$J$5295,Data!$M$2:$M$5295,$A11),"") | I11: =IFERROR(SUMIFS(Data!$N$2:$N$5295,Data!$M$2:$M$5295,$A11)/D11,"")
A14: Versions with 20 or more logged runs - chart source
A15: Tool version | B15: Sec per search (weighted) | C15: Avg time / run (sec) | D15: Chart label
A16: 2.4.1 | B16: =IFERROR(SUMIFS(Data!$P$2:$P$5295,Data!$M$2:$M$5295,$A16)/SUMIFS(Data!$H$2:$H$5295,Data!$M$2:$M$5295,$A16),"") | C16: =IFERROR(AVERAGEIFS(Data!$J$2:$J$5295,Data!$M$2:$M$5295,$A16),"") | D16: =$A16&" (n="&TEXT(COUNTIFS(Data!$M$2:$M$5295,$A16),"#,##0")&")"
A17: 2.5.12 | B17: =IFERROR(SUMIFS(Data!$P$2:$P$5295,Data!$M$2:$M$5295,$A17)/SUMIFS(Data!$H$2:$H$5295,Data!$M$2:$M$5295,$A17),"") | C17: =IFERROR(AVERAGEIFS(Data!$J$2:$J$5295,Data!$M$2:$M$5295,$A17),"") | D17: =$A17&" (n="&TEXT(COUNTIFS(Data!$M$2:$M$5295,$A17),"#,##0")&")"
A18: 3.4 | B18: =IFERROR(SUMIFS(Data!$P$2:$P$5295,Data!$M$2:$M$5295,$A18)/SUMIFS(Data!$H$2:$H$5295,Data!$M$2:$M$5295,$A18),"") | C18: =IFERROR(AVERAGEIFS(Data!$J$2:$J$5295,Data!$M$2:$M$5295,$A18),"") | D18: =$A18&" (n="&TEXT(COUNTIFS(Data!$M$2:$M$5295,$A18),"#,##0")&")"
A19: 3.5 | B19: =IFERROR(SUMIFS(Data!$P$2:$P$5295,Data!$M$2:$M$5295,$A19)/SUMIFS(Data!$H$2:$H$5295,Data!$M$2:$M$5295,$A19),"") | C19: =IFERROR(AVERAGEIFS(Data!$J$2:$J$5295,Data!$M$2:$M$5295,$A19),"") | D19: =$A19&" (n="&TEXT(COUNTIFS(Data!$M$2:$M$5295,$A19),"#,##0")&")"
A21: Versions 2.5.9, 2.5.10, 2.5.11 and 2.6.0 have fewer than 20 logged runs each (pilot and rollback traffic) and are listed above for completeness only.

Sheet Load Profile
A1: Does the tool slow down when more analysts run it at once?
A2: Each run is grouped by how many runs were logged across the estate in that same clock hour, then compared on seconds per search. A flat line means concurrency is not degrading performance.
A4: Runs in the same hour | B4: Baseline sec per search | C4: Current sec per search | D4: Baseline runs | E4: Current runs
A5: 1-2 | B5: =IFERROR(SUMIFS(Data!$P$2:$P$5295,Data!$S$2:$S$5295,$A5,Data!$B$2:$B$5295,"<=2026-06")/SUMIFS(Data!$H$2:$H$5295,Data!$S$2:$S$5295,$A5,Data!$B$2:$B$5295,"<=2026-06"),"") | C5: =IFERROR(SUMIFS(Data!$P$2:$P$5295,Data!$S$2:$S$5295,$A5,Data!$B$2:$B$5295,">=2026-07")/SUMIFS(Data!$H$2:$H$5295,Data!$S$2:$S$5295,$A5,Data!$B$2:$B$5295,">=2026-07"),"") | D5: =COUNTIFS(Data!$S$2:$S$5295,$A5,Data!$B$2:$B$5295,"<=2026-06") | E5: =COUNTIFS(Data!$S$2:$S$5295,$A5,Data!$B$2:$B$5295,">=2026-07")
A6: 3-5 | B6: =IFERROR(SUMIFS(Data!$P$2:$P$5295,Data!$S$2:$S$5295,$A6,Data!$B$2:$B$5295,"<=2026-06")/SUMIFS(Data!$H$2:$H$5295,Data!$S$2:$S$5295,$A6,Data!$B$2:$B$5295,"<=2026-06"),"") | C6: =IFERROR(SUMIFS(Data!$P$2:$P$5295,Data!$S$2:$S$5295,$A6,Data!$B$2:$B$5295,">=2026-07")/SUMIFS(Data!$H$2:$H$5295,Data!$S$2:$S$5295,$A6,Data!$B$2:$B$5295,">=2026-07"),"") | D6: =COUNTIFS(Data!$S$2:$S$5295,$A6,Data!$B$2:$B$5295,"<=2026-06") | E6: =COUNTIFS(Data!$S$2:$S$5295,$A6,Data!$B$2:$B$5295,">=2026-07")
A7: 6-10 | B7: =IFERROR(SUMIFS(Data!$P$2:$P$5295,Data!$S$2:$S$5295,$A7,Data!$B$2:$B$5295,"<=2026-06")/SUMIFS(Data!$H$2:$H$5295,Data!$S$2:$S$5295,$A7,Data!$B$2:$B$5295,"<=2026-06"),"") | C7: =IFERROR(SUMIFS(Data!$P$2:$P$5295,Data!$S$2:$S$5295,$A7,Data!$B$2:$B$5295,">=2026-07")/SUMIFS(Data!$H$2:$H$5295,Data!$S$2:$S$5295,$A7,Data!$B$2:$B$5295,">=2026-07"),"") | D7: =COUNTIFS(Data!$S$2:$S$5295,$A7,Data!$B$2:$B$5295,"<=2026-06") | E7: =COUNTIFS(Data!$S$2:$S$5295,$A7,Data!$B$2:$B$5295,">=2026-07")
A8: 11+ | B8: =IFERROR(SUMIFS(Data!$P$2:$P$5295,Data!$S$2:$S$5295,$A8,Data!$B$2:$B$5295,"<=2026-06")/SUMIFS(Data!$H$2:$H$5295,Data!$S$2:$S$5295,$A8,Data!$B$2:$B$5295,"<=2026-06"),"") | C8: =IFERROR(SUMIFS(Data!$P$2:$P$5295,Data!$S$2:$S$5295,$A8,Data!$B$2:$B$5295,">=2026-07")/SUMIFS(Data!$H$2:$H$5295,Data!$S$2:$S$5295,$A8,Data!$B$2:$B$5295,">=2026-07"),"") | D8: =COUNTIFS(Data!$S$2:$S$5295,$A8,Data!$B$2:$B$5295,"<=2026-06") | E8: =COUNTIFS(Data!$S$2:$S$5295,$A8,Data!$B$2:$B$5295,">=2026-07")
A10: Concurrency is measured from the audit log timestamps, so it reflects logged runs across the estate rather than confirmed simultaneous sessions.

Sheet Analyst Adoption
A1: Usage by analyst
A2: Sorted by runs logged. Case mix and entity counts differ by analyst, so this is a coverage and volume view rather than a comparison of individual performance.
A4: Analyst ID | B4: Runs | C4: Searches | D4: Entities | E4: Avg searches / run | F4: Sec per search (weighted) | G4: Avg time / run (sec) | H4: Tool hours consumed
A5: ssaha | B5: =COUNTIFS(Data!$E$2:$E$5295,$A5) | C5: =SUMIFS(Data!$H$2:$H$5295,Data!$E$2:$E$5295,$A5) | D5: =SUMIFS(Data!$G$2:$G$5295,Data!$E$2:$E$5295,$A5) | E5: =IFERROR(C5/B5,"") | F5: =IFERROR(SUMIFS(Data!$P$2:$P$5295,Data!$E$2:$E$5295,$A5)/C5,"") | G5: =IFERROR(AVERAGEIFS(Data!$J$2:$J$5295,Data!$E$2:$E$5295,$A5),"") | H5: =SUMIFS(Data!$J$2:$J$5295,Data!$E$2:$E$5295,$A5)/3600
A6: dchoudhury | B6: =COUNTIFS(Data!$E$2:$E$5295,$A6) | C6: =SUMIFS(Data!$H$2:$H$5295,Data!$E$2:$E$5295,$A6) | D6: =SUMIFS(Data!$G$2:$G$5295,Data!$E$2:$E$5295,$A6) | E6: =IFERROR(C6/B6,"") | F6: =IFERROR(SUMIFS(Data!$P$2:$P$5295,Data!$E$2:$E$5295,$A6)/C6,"") | G6: =IFERROR(AVERAGEIFS(Data!$J$2:$J$5295,Data!$E$2:$E$5295,$A6),"") | H6: =SUMIFS(Data!$J$2:$J$5295,Data!$E$2:$E$5295,$A6)/3600
A7: sswati | B7: =COUNTIFS(Data!$E$2:$E$5295,$A7) | C7: =SUMIFS(Data!$H$2:$H$5295,Data!$E$2:$E$5295,$A7) | D7: =SUMIFS(Data!$G$2:$G$5295,Data!$E$2:$E$5295,$A7) | E7: =IFERROR(C7/B7,"") | F7: =IFERROR(SUMIFS(Data!$P$2:$P$5295,Data!$E$2:$E$5295,$A7)/C7,"") | G7: =IFERROR(AVERAGEIFS(Data!$J$2:$J$5295,Data!$E$2:$E$5295,$A7),"") | H7: =SUMIFS(Data!$J$2:$J$5295,Data!$E$2:$E$5295,$A7)/3600
A8: hsindwani | B8: =COUNTIFS(Data!$E$2:$E$5295,$A8) | C8: =SUMIFS(Data!$H$2:$H$5295,Data!$E$2:$E$5295,$A8) | D8: =SUMIFS(Data!$G$2:$G$5295,Data!$E$2:$E$5295,$A8) | E8: =IFERROR(C8/B8,"") | F8: =IFERROR(SUMIFS(Data!$P$2:$P$5295,Data!$E$2:$E$5295,$A8)/C8,"") | G8: =IFERROR(AVERAGEIFS(Data!$J$2:$J$5295,Data!$E$2:$E$5295,$A8),"") | H8: =SUMIFS(Data!$J$2:$J$5295,Data!$E$2:$E$5295,$A8)/3600
A9: aghosh | B9: =COUNTIFS(Data!$E$2:$E$5295,$A9) | C9: =SUMIFS(Data!$H$2:$H$5295,Data!$E$2:$E$5295,$A9) | D9: =SUMIFS(Data!$G$2:$G$5295,Data!$E$2:$E$5295,$A9) | E9: =IFERROR(C9/B9,"") | F9: =IFERROR(SUMIFS(Data!$P$2:$P$5295,Data!$E$2:$E$5295,$A9)/C9,"") | G9: =IFERROR(AVERAGEIFS(Data!$J$2:$J$5295,Data!$E$2:$E$5295,$A9),"") | H9: =SUMIFS(Data!$J$2:$J$5295,Data!$E$2:$E$5295,$A9)/3600
A10: psathwika | B10: =COUNTIFS(Data!$E$2:$E$5295,$A10) | C10: =SUMIFS(Data!$H$2:$H$5295,Data!$E$2:$E$5295,$A10) | D10: =SUMIFS(Data!$G$2:$G$5295,Data!$E$2:$E$5295,$A10) | E10: =IFERROR(C10/B10,"") | F10: =IFERROR(SUMIFS(Data!$P$2:$P$5295,Data!$E$2:$E$5295,$A10)/C10,"") | G10: =IFERROR(AVERAGEIFS(Data!$J$2:$J$5295,Data!$E$2:$E$5295,$A10),"") | H10: =SUMIFS(Data!$J$2:$J$5295,Data!$E$2:$E$5295,$A10)/3600
A11: mgupta | B11: =COUNTIFS(Data!$E$2:$E$5295,$A11) | C11: =SUMIFS(Data!$H$2:$H$5295,Data!$E$2:$E$5295,$A11) | D11: =SUMIFS(Data!$G$2:$G$5295,Data!$E$2:$E$5295,$A11) | E11: =IFERROR(C11/B11,"") | F11: =IFERROR(SUMIFS(Data!$P$2:$P$5295,Data!$E$2:$E$5295,$A11)/C11,"") | G11: =IFERROR(AVERAGEIFS(Data!$J$2:$J$5295,Data!$E$2:$E$5295,$A11),"") | H11: =SUMIFS(Data!$J$2:$J$5295,Data!$E$2:$E$5295,$A11)/3600
A12: ssrinivasan | B12: =COUNTIFS(Data!$E$2:$E$5295,$A12) | C12: =SUMIFS(Data!$H$2:$H$5295,Data!$E$2:$E$5295,$A12) | D12: =SUMIFS(Data!$G$2:$G$5295,Data!$E$2:$E$5295,$A12) | E12: =IFERROR(C12/B12,"") | F12: =IFERROR(SUMIFS(Data!$P$2:$P$5295,Data!$E$2:$E$5295,$A12)/C12,"") | G12: =IFERROR(AVERAGEIFS(Data!$J$2:$J$5295,Data!$E$2:$E$5295,$A12),"") | H12: =SUMIFS(Data!$J$2:$J$5295,Data!$E$2:$E$5295,$A12)/3600
A13: shassan | B13: =COUNTIFS(Data!$E$2:$E$5295,$A13) | C13: =SUMIFS(Data!$H$2:$H$5295,Data!$E$2:$E$5295,$A13) | D13: =SUMIFS(Data!$G$2:$G$5295,Data!$E$2:$E$5295,$A13) | E13: =IFERROR(C13/B13,"") | F13: =IFERROR(SUMIFS(Data!$P$2:$P$5295,Data!$E$2:$E$5295,$A13)/C13,"") | G13: =IFERROR(AVERAGEIFS(Data!$J$2:$J$5295,Data!$E$2:$E$5295,$A13),"") | H13: =SUMIFS(Data!$J$2:$J$5295,Data!$E$2:$E$5295,$A13)/3600
A14: ns | B14: =COUNTIFS(Data!$E$2:$E$5295,$A14) | C14: =SUMIFS(Data!$H$2:$H$5295,Data!$E$2:$E$5295,$A14) | D14: =SUMIFS(Data!$G$2:$G$5295,Data!$E$2:$E$5295,$A14) | E14: =IFERROR(C14/B14,"") | F14: =IFERROR(SUMIFS(Data!$P$2:$P$5295,Data!$E$2:$E$5295,$A14)/C14,"") | G14: =IFERROR(AVERAGEIFS(Data!$J$2:$J$5295,Data!$E$2:$E$5295,$A14),"") | H14: =SUMIFS(Data!$J$2:$J$5295,Data!$E$2:$E$5295,$A14)/3600
A15: csaha | B15: =COUNTIFS(Data!$E$2:$E$5295,$A15) | C15: =SUMIFS(Data!$H$2:$H$5295,Data!$E$2:$E$5295,$A15) | D15: =SUMIFS(Data!$G$2:$G$5295,Data!$E$2:$E$5295,$A15) | E15: =IFERROR(C15/B15,"") | F15: =IFERROR(SUMIFS(Data!$P$2:$P$5295,Data!$E$2:$E$5295,$A15)/C15,"") | G15: =IFERROR(AVERAGEIFS(Data!$J$2:$J$5295,Data!$E$2:$E$5295,$A15),"") | H15: =SUMIFS(Data!$J$2:$J$5295,Data!$E$2:$E$5295,$A15)/3600
A16: stiwari | B16: =COUNTIFS(Data!$E$2:$E$5295,$A16) | C16: =SUMIFS(Data!$H$2:$H$5295,Data!$E$2:$E$5295,$A16) | D16: =SUMIFS(Data!$G$2:$G$5295,Data!$E$2:$E$5295,$A16) | E16: =IFERROR(C16/B16,"") | F16: =IFERROR(SUMIFS(Data!$P$2:$P$5295,Data!$E$2:$E$5295,$A16)/C16,"") | G16: =IFERROR(AVERAGEIFS(Data!$J$2:$J$5295,Data!$E$2:$E$5295,$A16),"") | H16: =SUMIFS(Data!$J$2:$J$5295,Data!$E$2:$E$5295,$A16)/3600
... A73: ykaushik | B73: =COUNTIFS(Data!$E$2:$E$5295,$A73) | C73: =SUMIFS(Data!$H$2:$H$5295,Data!$E$2:$E$5295,$A73) | D73: =SUMIFS(Data!$G$2:$G$5295,Data!$E$2:$E$5295,$A73) | E73: =IFERROR(C73/B73,"") | F73: =IFERROR(SUMIFS(Data!$P$2:$P$5295,Data!$E$2:$E$5295,$A73)/C73,"") | G73: =IFERROR(AVERAGEIFS(Data!$J$2:$J$5295,Data!$E$2:$E$5295,$A73),"") | H73: =SUMIFS(Data!$J$2:$J$5295,Data!$E$2:$E$5295,$A73)/3600

Sheet Notes & Method
B2: Method, definitions and caveats
B4: Source | C4: Sheet1 of the shared master tracker - the audit log the OSDD tool writes on each run. Extracted 17 Aug 2026.
B5: Rows in source | C5: 5,390
B6: Rows used | C6: 5,294 - rows with a parseable "Time Taken" value.
B7: Rows excluded | C7: 96 rows carried a timestamp but no analyst, case, counts or duration. These are partial tracker writes rather than zero-length runs, so including them would bias every average. Usage figures in this workbook are therefore a slight undercount.
B8: Time parsing | C8: Column J of the Data tab parses the free-text duration: the number before the word "minute" x 60, plus the number following "and". Only two formats occur in the source - "N second(s)" and "N minute(s) and N second(s)". No durations are hardcoded; the sheet recalculates if the source text changes.
B9: Time metrics order | C9: Where time per run is shown at more than one point of the distribution, the columns and chart series run smallest to largest: median, then average, then P90.
B10: Two-component model | C10: Run duration is modelled as fixed overhead + (marginal seconds per search x number of searches), fitted by least squares on each month's runs (INTERCEPT, SLOPE, RSQ). Fixed overhead is the part of a run independent of search count; the marginal figure is the cost of each additional search. Runs logging zero searches are included in the fit as low-volume points.
B11: Sample sizes on charts | C11: Monthly chart categories carry the number of runs behind each point (Monthly Pivot column U), so months with thin coverage - Apr-2026 at 22 runs, Aug-2026 partial - are not read as trend.
B12: Completion curve | C12: Cumulative share of runs finishing within each duration, baseline period against current period. Answers how long an analyst waits rather than what the mean is.
B13: Concurrency band | C13: Each run is tagged with how many runs were logged across the estate in the same clock hour (Data columns Q to S), then grouped into bands. Derived from audit-log timestamps, so it reflects logged activity rather than confirmed simultaneous sessions.
B14: Sec per search (weighted) | C14: Total run seconds divided by total searches for the group. Preferred over averaging each run's own ratio, which over-weights single-search runs.
B15: Active analysts | C15: Distinct analyst IDs with at least one logged run in the month.
... B21: Native PivotTable | C21: The Data tab is an Excel Table named tblRuns. Insert > PivotTable > Table/Range: tblRuns creates a live pivot; use Month Key as rows and Seconds, Total Searches and Seconds per Search as values. The Monthly Pivot tab mirrors that output using formulas, so it needs no refresh.

Sheet Data
A1: Date & Time | B1: Month Key | C1: Month Label | D1: Week Start | E1: Analyst ID | F1: ECM Case ID | G1: Total Entities | H1: Total Searches | I1: Time Taken (raw) | J1: Seconds | K1: Minutes | L1: Seconds per Search | M1: Tool Version | N1: Over 5 Min | O1: Over 10 Min | P1: Seconds (rated runs) | Q1: Hour Key | R1: Runs in Same Hour | S1: Concurrency Band
A2: 46142.09 | B2: =TEXT(A2,"YYYY-MM") | C2: =TEXT(A2,"MMM-YYYY") | D2: =INT(A2)-WEEKDAY(A2,2)+1 | E2: asahoo | F2: 93944 | G2: 1 | H2: 3 | I2: 2 minute(s) and 12 second(s) | J2: =IFERROR(VALUE(TRIM(LEFT(I2,FIND("minute",I2)-1)))*60,0)+IFERROR(VALUE(SUBSTITUTE(MID(I2,IFERROR(FIND("and",I2)+3,1),20),"second(s)","")),0) | K2: =J2/60 | L2: =IFERROR(J2/H2,"") | M2: 2.4.1 | N2: =IF(J2>300,1,0) | O2: =IF(J2>600,1,0) | P2: =IF(H2>0,J2,"") | Q2: =TEXT(A2,"YYYY-MM-DD HH") | R2: =COUNTIF($Q$2:$Q$5295,Q2) | S2: =IF(R2<=2,"1-2",IF(R2<=5,"3-5",IF(R2<=10,"6-10","11+")))
A3: 46142.094 | B3: =TEXT(A3,"YYYY-MM") | C3: =TEXT(A3,"MMM-YYYY") | D3: =INT(A3)-WEEKDAY(A3,2)+1 | E3: asahoo | F3: 84646 | G3: 1 | H3: 1 | I3: 32 second(s) | J3: =IFERROR(VALUE(TRIM(LEFT(I3,FIND("minute",I3)-1)))*60,0)+IFERROR(VALUE(SUBSTITUTE(MID(I3,IFERROR(FIND("and",I3)+3,1),20),"second(s)","")),0) | K3: =J3/60 | L3: =IFERROR(J3/H3,"") | M3: 2.4.1 | N3: =IF(J3>300,1,0) | O3: =IF(J3>600,1,0) | P3: =IF(H3>0,J3,"") | Q3: =TEXT(A3,"YYYY-MM-DD HH") | R3: =COUNTIF($Q$2:$Q$5295,Q3) | S3: =IF(R3<=2,"1-2",IF(R3<=5,"3-5",IF(R3<=10,"6-10","11+")))
A4: 46142.097 | B4: =TEXT(A4,"YYYY-MM") | C4: =TEXT(A4,"MMM-YYYY") | D4: =INT(A4)-WEEKDAY(A4,2)+1 | E4: ns | F4: 12345 | G4: 1 | H4: 1 | I4: 36 second(s) | J4: =IFERROR(VALUE(TRIM(LEFT(I4,FIND("minute",I4)-1)))*60,0)+IFERROR(VALUE(SUBSTITUTE(MID(I4,IFERROR(FIND("and",I4)+3,1),20),"second(s)","")),0) | K4: =J4/60 | L4: =IFERROR(J4/H4,"") | M4: 2.4.1 | N4: =IF(J4>300,1,0) | O4: =IF(J4>600,1,0) | P4: =IF(H4>0,J4,"") | Q4: =TEXT(A4,"YYYY-MM-DD HH") | R4: =COUNTIF($Q$2:$Q$5295,Q4) | S4: =IF(R4<=2,"1-2",IF(R4<=5,"3-5",IF(R4<=10,"6-10","11+")))
A5: 46142.111 | B5: =TEXT(A5,"YYYY-MM") | C5: =TEXT(A5,"MMM-YYYY") | D5: =INT(A5)-WEEKDAY(A5,2)+1 | E5: ns | F5: 98684 | G5: 1 | H5: 7 | I5: 4 minute(s) and 28 second(s) | J5: =IFERROR(VALUE(TRIM(LEFT(I5,FIND("minute",I5)-1)))*60,0)+IFERROR(VALUE(SUBSTITUTE(MID(I5,IFERROR(FIND("and",I5)+3,1),20),"second(s)","")),0) | K5: =J5/60 | L5: =IFERROR(J5/H5,"") | M5: 2.4.1 | N5: =IF(J5>300,1,0) | O5: =IF(J5>600,1,0) | P5: =IF(H5>0,J5,"") | Q5: =TEXT(A5,"YYYY-MM-DD HH") | R5: =COUNTIF($Q$2:$Q$5295,Q5) | S5: =IF(R5<=2,"1-2",IF(R5<=5,"3-5",IF(R5<=10,"6-10","11+")))
A6: 46142.124 | B6: =TEXT(A6,"YYYY-MM") | C6: =TEXT(A6,"MMM-YYYY") | D6: =INT(A6)-WEEKDAY(A6,2)+1 | E6: ns | F6: 98684 | G6: 3 | H6: 14 | I6: 10 minute(s) and 22 second(s) | J6: =IFERROR(VALUE(TRIM(LEFT(I6,FIND("minute",I6)-1)))*60,0)+IFERROR(VALUE(SUBSTITUTE(MID(I6,IFERROR(FIND("and",I6)+3,1),20),"second(s)","")),0) | K6: =J6/60 | L6: =IFERROR(J6/H6,"") | M6: 2.4.1 | N6: =IF(J6>300,1,0) | O6: =IF(J6>600,1,0) | P6: =IF(H6>0,J6,"") | Q6: =TEXT(A6,"YYYY-MM-DD HH") | R6: =COUNTIF($Q$2:$Q$5295,Q6) | S6: =IF(R6<=2,"1-2",IF(R6<=5,"3-5",IF(R6<=10,"6-10","11+")))
A7: 46142.32 | B7: =TEXT(A7,"YYYY-MM") | C7: =TEXT(A7,"MMM-YYYY") | D7: =INT(A7)-WEEKDAY(A7,2)+1 | E7: emishra | F7: 71626 | G7: 5 | H7: 31 | I7: 15 minute(s) and 19 second(s) | J7: =IFERROR(VALUE(TRIM(LEFT(I7,FIND("minute",I7)-1)))*60,0)+IFERROR(VALUE(SUBSTITUTE(MID(I7,IFERROR(FIND("and",I7)+3,1),20),"second(s)","")),0) | K7: =J7/60 | L7: =IFERROR(J7/H7,"") | M7: 2.4.1 | N7: =IF(J7>300,1,0) | O7: =IF(J7>600,1,0) | P7: =IF(H7>0,J7,"") | Q7: =TEXT(A7,"YYYY-MM-DD HH") | R7: =COUNTIF($Q$2:$Q$5295,Q7) | S7: =IF(R7<=2,"1-2",IF(R7<=5,"3-5",IF(R7<=10,"6-10","11+")))
A8: 46142.457 | B8: =TEXT(A8,"YYYY-MM") | C8: =TEXT(A8,"MMM-YYYY") | D8: =INT(A8)-WEEKDAY(A8,2)+1 | E8: aghosh | F8: 22136 | G8: 5 | H8: 25 | I8: 20 minute(s) and 51 second(s) | J8: =IFERROR(VALUE(TRIM(LEFT(I8,FIND("minute",I8)-1)))*60,0)+IFERROR(VALUE(SUBSTITUTE(MID(I8,IFERROR(FIND("and",I8)+3,1),20),"second(s)","")),0) | K8: =J8/60 | L8: =IFERROR(J8/H8,"") | M8: 2.4.1 | N8: =IF(J8>300,1,0) | O8: =IF(J8>600,1,0) | P8: =IF(H8>0,J8,"") | Q8: =TEXT(A8,"YYYY-MM-DD HH") | R8: =COUNTIF($Q$2:$Q$5295,Q8) | S8: =IF(R8<=2,"1-2",IF(R8<=5,"3-5",IF(R8<=10,"6-10","11+")))
A9: 46142.487 | B9: =TEXT(A9,"YYYY-MM") | C9: =TEXT(A9,"MMM-YYYY") | D9: =INT(A9)-WEEKDAY(A9,2)+1 | E9: ssaha | F9: 12345 | G9: 1 | H9: 1 | I9: 54 second(s) | J9: =IFERROR(VALUE(TRIM(LEFT(I9,FIND("minute",I9)-1)))*60,0)+IFERROR(VALUE(SUBSTITUTE(MID(I9,IFERROR(FIND("and",I9)+3,1),20),"second(s)","")),0) | K9: =J9/60 | L9: =IFERROR(J9/H9,"") | M9: 2.4.1 | N9: =IF(J9>300,1,0) | O9: =IF(J9>600,1,0) | P9: =IF(H9>0,J9,"") | Q9: =TEXT(A9,"YYYY-MM-DD HH") | R9: =COUNTIF($Q$2:$Q$5295,Q9) | S9: =IF(R9<=2,"1-2",IF(R9<=5,"3-5",IF(R9<=10,"6-10","11+")))
A10: 46142.493 | B10: =TEXT(A10,"YYYY-MM") | C10: =TEXT(A10,"MMM-YYYY") | D10: =INT(A10)-WEEKDAY(A10,2)+1 | E10: ssaha | F10: 542134 | G10: 1 | H10: 0 | I10: 5 minute(s) and 58 second(s) | J10: =IFERROR(VALUE(TRIM(LEFT(I10,FIND("minute",I10)-1)))*60,0)+IFERROR(VALUE(SUBSTITUTE(MID(I10,IFERROR(FIND("and",I10)+3,1),20),"second(s)","")),0) | K10: =J10/60 | L10: =IFERROR(J10/H10,"") | M10: 2.4.1 | N10: =IF(J10>300,1,0) | O10: =IF(J10>600,1,0) | P10: =IF(H10>0,J10,"") | Q10: =TEXT(A10,"YYYY-MM-DD HH") | R10: =COUNTIF($Q$2:$Q$5295,Q10) | S10: =IF(R10<=2,"1-2",IF(R10<=5,"3-5",IF(R10<=10,"6-10","11+")))
A11: 46142.509 | B11: =TEXT(A11,"YYYY-MM") | C11: =TEXT(A11,"MMM-YYYY") | D11: =INT(A11)-WEEKDAY(A11,2)+1 | E11: csaha | F11: 36648 | G11: 4 | H11: 14 | I11: 8 minute(s) and 16 second(s) | J11: =IFERROR(VALUE(TRIM(LEFT(I11,FIND("minute",I11)-1)))*60,0)+IFERROR(VALUE(SUBSTITUTE(MID(I11,IFERROR(FIND("and",I11)+3,1),20),"second(s)","")),0) | K11: =J11/60 | L11: =IFERROR(J11/H11,"") | M11: 2.4.1 | N11: =IF(J11>300,1,0) | O11: =IF(J11>600,1,0) | P11: =IF(H11>0,J11,"") | Q11: =TEXT(A11,"YYYY-MM-DD HH") | R11: =COUNTIF($Q$2:$Q$5295,Q11) | S11: =IF(R11<=2,"1-2",IF(R11<=5,"3-5",IF(R11<=10,"6-10","11+")))
A12: 46142.518 | B12: =TEXT(A12,"YYYY-MM") | C12: =TEXT(A12,"MMM-YYYY") | D12: =INT(A12)-WEEKDAY(A12,2)+1 | E12: csaha | F12: 36648 | G12: 4 | H12: 14 | I12: 9 minute(s) and 14 second(s) | J12: =IFERROR(VALUE(TRIM(LEFT(I12,FIND("minute",I12)-1)))*60,0)+IFERROR(VALUE(SUBSTITUTE(MID(I12,IFERROR(FIND("and",I12)+3,1),20),"second(s)","")),0) | K12: =J12/60 | L12: =IFERROR(J12/H12,"") | M12: 2.4.1 | N12: =IF(J12>300,1,0) | O12: =IF(J12>600,1,0) | P12: =IF(H12>0,J12,"") | Q12: =TEXT(A12,"YYYY-MM-DD HH") | R12: =COUNTIF($Q$2:$Q$5295,Q12) | S12: =IF(R12<=2,"1-2",IF(R12<=5,"3-5",IF(R12<=10,"6-10","11+")))
A13: 46142.542 | B13: =TEXT(A13,"YYYY-MM") | C13: =TEXT(A13,"MMM-YYYY") | D13: =INT(A13)-WEEKDAY(A13,2)+1 | E13: msrivastava | F13: 4565 | G13: 1 | H13: 1 | I13: 30 second(s) | J13: =IFERROR(VALUE(TRIM(LEFT(I13,FIND("minute",I13)-1)))*60,0)+IFERROR(VALUE(SUBSTITUTE(MID(I13,IFERROR(FIND("and",I13)+3,1),20),"second(s)","")),0) | K13: =J13/60 | L13: =IFERROR(J13/H13,"") | M13: 2.4.1 | N13: =IF(J13>300,1,0) | O13: =IF(J13>600,1,0) | P13: =IF(H13>0,J13,"") | Q13: =TEXT(A13,"YYYY-MM-DD HH") | R13: =COUNTIF($Q$2:$Q$5295,Q13) | S13: =IF(R13<=2,"1-2",IF(R13<=5,"3-5",IF(R13<=10,"6-10","11+")))
... A2668: 46188.958 | B2668: =TEXT(A2668,"YYYY-MM") | C2668: =TEXT(A2668,"MMM-YYYY") | D2668: =INT(A2668)-WEEKDAY(A2668,2)+1 | E2668: ssarkar | F2668: 125252 | G2668: 2 | H2668: 10 | I2668: 3 minute(s) and 43 second(s) | J2668: =IFERROR(VALUE(TRIM(LEFT(I2668,FIND("minute",I2668)-1)))*60,0)+IFERROR(VALUE(SUBSTITUTE(MID(I2668,IFERROR(FIND("and",I2668)+3,1),20),"second(s)","")),0) | K2668: =J2668/60 | L2668: =IFERROR(J2668/H2668,"") | M2668: 2.5.12 | N2668: =IF(J2668>300,1,0) | O2668: =IF(J2668>600,1,0) | P2668: =IF(H2668>0,J2668,"") | Q2668: =TEXT(A2668,"YYYY-MM-DD HH") | R2668: =COUNTIF($Q$2:$Q$5295,Q2668) | S2668: =IF(R2668<=2,"1-2",IF(R2668<=5,"3-5",IF(R2668<=10,"6-10","11+")))
A2669: 46188.973 | B2669: =TEXT(A2669,"YYYY-MM") | C2669: =TEXT(A2669,"MMM-YYYY") | D2669: =INT(A2669)-WEEKDAY(A2669,2)+1 | E2669: ssaha | F2669: Test 2 | G2669: 1 | H2669: 5 | I2669: 2 minute(s) and 23 second(s) | J2669: =IFERROR(VALUE(TRIM(LEFT(I2669,FIND("minute",I2669)-1)))*60,0)+IFERROR(VALUE(SUBSTITUTE(MID(I2669,IFERROR(FIND("and",I2669)+3,1),20),"second(s)","")),0) | K2669: =J2669/60 | L2669: =IFERROR(J2669/H2669,"") | M2669: 2.5.12 | N2669: =IF(J2669>300,1,0) | O2669: =IF(J2669>600,1,0) | P2669: =IF(H2669>0,J2669,"") | Q2669: =TEXT(A2669,"YYYY-MM-DD HH") | R2669: =COUNTIF($Q$2:$Q$5295,Q2669) | S2669: =IF(R2669<=2,"1-2",IF(R2669<=5,"3-5",IF(R2669<=10,"6-10","11+")))
A2670: 46188.976 | B2670: =TEXT(A2670,"YYYY-MM") | C2670: =TEXT(A2670,"MMM-YYYY") | D2670: =INT(A2670)-WEEKDAY(A2670,2)+1 | E2670: psingh | F2670: 123572 | G2670: 2 | H2670: 10 | I2670: 4 minute(s) and 2 second(s) | J2670: =IFERROR(VALUE(TRIM(LEFT(I2670,FIND("minute",I2670)-1)))*60,0)+IFERROR(VALUE(SUBSTITUTE(MID(I2670,IFERROR(FIND("and",I2670)+3,1),20),"second(s)","")),0) | K2670: =J2670/60 | L2670: =IFERROR(J2670/H2670,"") | M2670: 2.5.12 | N2670: =IF(J2670>300,1,0) | O2670: =IF(J2670>600,1,0) | P2670: =IF(H2670>0,J2670,"") | Q2670: =TEXT(A2670,"YYYY-MM-DD HH") | R2670: =COUNTIF($Q$2:$Q$5295,Q2670) | S2670: =IF(R2670<=2,"1-2",IF(R2670<=5,"3-5",IF(R2670<=10,"6-10","11+")))
A2671: 46189.049 | B2671: =TEXT(A2671,"YYYY-MM") | C2671: =TEXT(A2671,"MMM-YYYY") | D2671: =INT(A2671)-WEEKDAY(A2671,2)+1 | E2671: shassan | F2671: 125276 | G2671: 2 | H2671: 10 | I2671: 2 minute(s) and 9 second(s) | J2671: =IFERROR(VALUE(TRIM(LEFT(I2671,FIND("minute",I2671)-1)))*60,0)+IFERROR(VALUE(SUBSTITUTE(MID(I2671,IFERROR(FIND("and",I2671)+3,1),20),"second(s)","")),0) | K2671: =J2671/60 | L2671: =IFERROR(J2671/H2671,"") | M2671: 2.5.12 | N2671: =IF(J2671>300,1,0) | O2671: =IF(J2671>600,1,0) | P2671: =IF(H2671>0,J2671,"") | Q2671: =TEXT(A2671,"YYYY-MM-DD HH") | R2671: =COUNTIF($Q$2:$Q$5295,Q2671) | S2671: =IF(R2671<=2,"1-2",IF(R2671<=5,"3-5",IF(R2671<=10,"6-10","11+")))
A2672: 46189.085 | B2672: =TEXT(A2672,"YYYY-MM") | C2672: =TEXT(A2672,"MMM-YYYY") | D2672: =INT(A2672)-WEEKDAY(A2672,2)+1 | E2672: anusharma | F2672: 124268 | G2672: 4 | H2672: 16 | I2672: 6 minute(s) and 11 second(s) | J2672: =IFERROR(VALUE(TRIM(LEFT(I2672,FIND("minute",I2672)-1)))*60,0)+IFERROR(VALUE(SUBSTITUTE(MID(I2672,IFERROR(FIND("and",I2672)+3,1),20),"second(s)","")),0) | K2672: =J2672/60 | L2672: =IFERROR(J2672/H2672,"") | M2672: 2.5.12 | N2672: =IF(J2672>300,1,0) | O2672: =IF(J2672>600,1,0) | P2672: =IF(H2672>0,J2672,"") | Q2672: =TEXT(A2672,"YYYY-MM-DD HH") | R2672: =COUNTIF($Q$2:$Q$5295,Q2672) | S2672: =IF(R2672<=2,"1-2",IF(R2672<=5,"3-5",IF(R2672<=10,"6-10","11+")))
A2673: 46189.091 | B2673: =TEXT(A2673,"YYYY-MM") | C2673: =TEXT(A2673,"MMM-YYYY") | D2673: =INT(A2673)-WEEKDAY(A2673,2)+1 | E2673: mbohra | F2673: 125206 | G2673: 4 | H2673: 20 | I2673: 7 minute(s) and 45 second(s) | J2673: =IFERROR(VALUE(TRIM(LEFT(I2673,FIND("minute",I2673)-1)))*60,0)+IFERROR(VALUE(SUBSTITUTE(MID(I2673,IFERROR(FIND("and",I2673)+3,1),20),"second(s)","")),0) | K2673: =J2673/60 | L2673: =IFERROR(J2673/H2673,"") | M2673: 2.5.12 | N2673: =IF(J2673>300,1,0) | O2673: =IF(J2673>600,1,0) | P2673: =IF(H2673>0,J2673,"") | Q2673: =TEXT(A2673,"YYYY-MM-DD HH") | R2673: =COUNTIF($Q$2:$Q$5295,Q2673) | S2673: =IF(R2673<=2,"1-2",IF(R2673<=5,"3-5",IF(R2673<=10,"6-10","11+")))
A2674: 46189.093 | B2674: =TEXT(A2674,"YYYY-MM") | C2674: =TEXT(A2674,"MMM-YYYY") | D2674: =INT(A2674)-WEEKDAY(A2674,2)+1 | E2674: shassan | F2674: 125275 | G2674: 2 | H2674: 8 | I2674: 3 minute(s) and 38 second(s) | J2674: =IFERROR(VALUE(TRIM(LEFT(I2674,FIND("minute",I2674)-1)))*60,0)+IFERROR(VALUE(SUBSTITUTE(MID(I2674,IFERROR(FIND("and",I2674)+3,1),20),"second(s)","")),0) | K2674: =J2674/60 | L2674: =IFERROR(J2674/H2674,"") | M2674: 2.5.12 | N2674: =IF(J2674>300,1,0) | O2674: =IF(J2674>600,1,0) | P2674: =IF(H2674>0,J2674,"") | Q2674: =TEXT(A2674,"YYYY-MM-DD HH") | R2674: =COUNTIF($Q$2:$Q$5295,Q2674) | S2674: =IF(R2674<=2,"1-2",IF(R2674<=5,"3-5",IF(R2674<=10,"6-10","11+")))
A2675: 46189.099 | B2675: =TEXT(A2675,"YYYY-MM") | C2675: =TEXT(A2675,"MMM-YYYY") | D2675: =INT(A2675)-WEEKDAY(A2675,2)+1 | E2675: ns | F2675: 124772 | G2675: 1 | H2675: 5 | I2675: 2 minute(s) and 55 second(s) | J2675: =IFERROR(VALUE(TRIM(LEFT(I2675,FIND("minute",I2675)-1)))*60,0)+IFERROR(VALUE(SUBSTITUTE(MID(I2675,IFERROR(FIND("and",I2675)+3,1),20),"second(s)","")),0) | K2675: =J2675/60 | L2675: =IFERROR(J2675/H2675,"") | M2675: 2.5.12 | N2675: =IF(J2675>300,1,0) | O2675: =IF(J2675>600,1,0) | P2675: =IF(H2675>0,J2675,"") | Q2675: =TEXT(A2675,"YYYY-MM-DD HH") | R2675: =COUNTIF($Q$2:$Q$5295,Q2675) | S2675: =IF(R2675<=2,"1-2",IF(R2675<=5,"3-5",IF(R2675<=10,"6-10","11+")))
A2676: 46189.1 | B2676: =TEXT(A2676,"YYYY-MM") | C2676: =TEXT(A2676,"MMM-YYYY") | D2676: =INT(A2676)-WEEKDAY(A2676,2)+1 | E2676: adey | F2676: 124340 | G2676: 2 | H2676: 10 | I2676: 2 minute(s) and 47 second(s) | J2676: =IFERROR(VALUE(TRIM(LEFT(I2676,FIND("minute",I2676)-1)))*60,0)+IFERROR(VALUE(SUBSTITUTE(MID(I2676,IFERROR(FIND("and",I2676)+3,1),20),"second(s)","")),0) | K2676: =J2676/60 | L2676: =IFERROR(J2676/H2676,"") | M2676: 2.5.12 | N2676: =IF(J2676>300,1,0) | O2676: =IF(J2676>600,1,0) | P2676: =IF(H2676>0,J2676,"") | Q2676: =TEXT(A2676,"YYYY-MM-DD HH") | R2676: =COUNTIF($Q$2:$Q$5295,Q2676) | S2676: =IF(R2676<=2,"1-2",IF(R2676<=5,"3-5",IF(R2676<=10,"6-10","11+")))
A2677: 46189.101 | B2677: =TEXT(A2677,"YYYY-MM") | C2677: =TEXT(A2677,"MMM-YYYY") | D2677: =INT(A2677)-WEEKDAY(A2677,2)+1 | E2677: aghosh | F2677: 123648 | G2677: 1 | H2677: 7 | I2677: 4 minute(s) and 27 second(s) | J2677: =IFERROR(VALUE(TRIM(LEFT(I2677,FIND("minute",I2677)-1)))*60,0)+IFERROR(VALUE(SUBSTITUTE(MID(I2677,IFERROR(FIND("and",I2677)+3,1),20),"second(s)","")),0) | K2677: =J2677/60 | L2677: =IFERROR(J2677/H2677,"") | M2677: 2.5.12 | N2677: =IF(J2677>300,1,0) | O2677: =IF(J2677>600,1,0) | P2677: =IF(H2677>0,J2677,"") | Q2677: =TEXT(A2677,"YYYY-MM-DD HH") | R2677: =COUNTIF($Q$2:$Q$5295,Q2677) | S2677: =IF(R2677<=2,"1-2",IF(R2677<=5,"3-5",IF(R2677<=10,"6-10","11+")))
A2678: 46189.102 | B2678: =TEXT(A2678,"YYYY-MM") | C2678: =TEXT(A2678,"MMM-YYYY") | D2678: =INT(A2678)-WEEKDAY(A2678,2)+1 | E2678: sdey | F2678: 125262 | G2678: 3 | H2678: 11 | I2678: 3 minute(s) and 10 second(s) | J2678: =IFERROR(VALUE(TRIM(LEFT(I2678,FIND("minute",I2678)-1)))*60,0)+IFERROR(VALUE(SUBSTITUTE(MID(I2678,IFERROR(FIND("and",I2678)+3,1),20),"second(s)","")),0) | K2678: =J2678/60 | L2678: =IFERROR(J2678/H2678,"") | M2678: 2.5.12 | N2678: =IF(J2678>300,1,0) | O2678: =IF(J2678>600,1,0) | P2678: =IF(H2678>0,J2678,"") | Q2678: =TEXT(A2678,"YYYY-MM-DD HH") | R2678: =COUNTIF($Q$2:$Q$5295,Q2678) | S2678: =IF(R2678<=2,"1-2",IF(R2678<=5,"3-5",IF(R2678<=10,"6-10","11+")))
A2679: 46189.107 | B2679: =TEXT(A2679,"YYYY-MM") | C2679: =TEXT(A2679,"MMM-YYYY") | D2679: =INT(A2679)-WEEKDAY(A2679,2)+1 | E2679: csaha | F2679: 124368 | G2679: 4 | H2679: 12 | I2679: 2 minute(s) and 50 second(s) | J2679: =IFERROR(VALUE(TRIM(LEFT(I2679,FIND("minute",I2679)-1)))*60,0)+IFERROR(VALUE(SUBSTITUTE(MID(I2679,IFERROR(FIND("and",I2679)+3,1),20),"second(s)","")),0) | K2679: =J2679/60 | L2679: =IFERROR(J2679/H2679,"") | M2679: 2.5.12 | N2679: =IF(J2679>300,1,0) | O2679: =IF(J2679>600,1,0) | P2679: =IF(H2679>0,J2679,"") | Q2679: =TEXT(A2679,"YYYY-MM-DD HH") | R2679: =COUNTIF($Q$2:$Q$5295,Q2679) | S2679: =IF(R2679<=2,"1-2",IF(R2679<=5,"3-5",IF(R2679<=10,"6-10","11+")))
A2680: 46189.118 | B2680: =TEXT(A2680,"YYYY-MM") | C2680: =TEXT(A2680,"MMM-YYYY") | D2680: =INT(A2680)-WEEKDAY(A2680,2)+1 | E2680: tkarmakar | F2680: 123780 | G2680: 1 | H2680: 5 | I2680: 2 minute(s) and 47 second(s) | J2680: =IFERROR(VALUE(TRIM(LEFT(I2680,FIND("minute",I2680)-1)))*60,0)+IFERROR(VALUE(SUBSTITUTE(MID(I2680,IFERROR(FIND("and",I2680)+3,1),20),"second(s)","")),0) | K2680: =J2680/60 | L2680: =IFERROR(J2680/H2680,"") | M2680: 2.5.12 | N2680: =IF(J2680>300,1,0) | O2680: =IF(J2680>600,1,0) | P2680: =IF(H2680>0,J2680,"") | Q2680: =TEXT(A2680,"YYYY-MM-DD HH") | R2680: =COUNTIF($Q$2:$Q$5295,Q2680) | S2680: =IF(R2680<=2,"1-2",IF(R2680<=5,"3-5",IF(R2680<=10,"6-10","11+")))
A2681: 46189.129 | B2681: =TEXT(A2681,"YYYY-MM") | C2681: =TEXT(A2681,"MMM-YYYY") | D2681: =INT(A2681)-WEEKDAY(A2681,2)+1 | E2681: shassan | F2681: 124307 | G2681: 4 | H2681: 10 | I2681: 2 minute(s) and 44 second(s) | J2681: =IFERROR(VALUE(TRIM(LEFT(I2681,FIND("minute",I2681)-1)))*60,0)+IFERROR(VALUE(SUBSTITUTE(MID(I2681,IFERROR(FIND("and",I2681)+3,1),20),"second(s)","")),0) | K2681: =J2681/60 | L2681: =IFERROR(J2681/H2681,"") | M2681: 2.5.12 | N2681: =IF(J2681>300,1,0) | O2681: =IF(J2681>600,1,0) | P2681: =IF(H2681>0,J2681,"") | Q2681: =TEXT(A2681,"YYYY-MM-DD HH") | R2681: =COUNTIF($Q$2:$Q$5295,Q2681) | S2681: =IF(R2681<=2,"1-2",IF(R2681<=5,"3-5",IF(R2681<=10,"6-10","11+")))
... A3044: 46195.828 | B3044: =TEXT(A3044,"YYYY-MM") | C3044: =TEXT(A3044,"MMM-YYYY") | D3044: =INT(A3044)-WEEKDAY(A3044,2)+1 | E3044: ssarkar | F3044: 112606 | G3044: 2 | H3044: 10 | I3044: 2 minute(s) and 37 second(s) | J3044: =IFERROR(VALUE(TRIM(LEFT(I3044,FIND("minute",I3044)-1)))*60,0)+IFERROR(VALUE(SUBSTITUTE(MID(I3044,IFERROR(FIND("and",I3044)+3,1),20),"second(s)","")),0) | K3044: =J3044/60 | L3044: =IFERROR(J3044/H3044,"") | M3044: 2.5.12 | N3044: =IF(J3044>300,1,0) | O3044: =IF(J3044>600,1,0) | P3044: =IF(H3044>0,J3044,"") | Q3044: =TEXT(A3044,"YYYY-MM-DD HH") | R3044: =COUNTIF($Q$2:$Q$5295,Q3044) | S3044: =IF(R3044<=2,"1-2",IF(R3044<=5,"3-5",IF(R3044<=10,"6-10","11+")))
A3045: 46195.829 | B3045: =TEXT(A3045,"YYYY-MM") | C3045: =TEXT(A3045,"MMM-YYYY") | D3045: =INT(A3045)-WEEKDAY(A3045,2)+1 | E3045: ssaha | F3045: test | G3045: 1 | H3045: 1 | I3045: 40 second(s) | J3045: =IFERROR(VALUE(TRIM(LEFT(I3045,FIND("minute",I3045)-1)))*60,0)+IFERROR(VALUE(SUBSTITUTE(MID(I3045,IFERROR(FIND("and",I3045)+3,1),20),"second(s)","")),0) | K3045: =J3045/60 | L3045: =IFERROR(J3045/H3045,"") | M3045: 2.5.12 | N3045: =IF(J3045>300,1,0) | O3045: =IF(J3045>600,1,0) | P3045: =IF(H3045>0,J3045,"") | Q3045: =TEXT(A3045,"YYYY-MM-DD HH") | R3045: =COUNTIF($Q$2:$Q$5295,Q3045) | S3045: =IF(R3045<=2,"1-2",IF(R3045<=5,"3-5",IF(R3045<=10,"6-10","11+")))
A3046: 46195.884 | B3046: =TEXT(A3046,"YYYY-MM") | C3046: =TEXT(A3046,"MMM-YYYY") | D3046: =INT(A3046)-WEEKDAY(A3046,2)+1 | E3046: ssarkar | F3046: 109913 | G3046: 3 | H3046: 11 | I3046: 3 minute(s) and 40 second(s) | J3046: =IFERROR(VALUE(TRIM(LEFT(I3046,FIND("minute",I3046)-1)))*60,0)+IFERROR(VALUE(SUBSTITUTE(MID(I3046,IFERROR(FIND("and",I3046)+3,1),20),"second(s)","")),0) | K3046: =J3046/60 | L3046: =IFERROR(J3046/H3046,"") | M3046: 2.5.12 | N3046: =IF(J3046>300,1,0) | O3046: =IF(J3046>600,1,0) | P3046: =IF(H3046>0,J3046,"") | Q3046: =TEXT(A3046,"YYYY-MM-DD HH") | R3046: =COUNTIF($Q$2:$Q$5295,Q3046) | S3046: =IF(R3046<=2,"1-2",IF(R3046<=5,"3-5",IF(R3046<=10,"6-10","11+")))
A3047: 46195.888 | B3047: =TEXT(A3047,"YYYY-MM") | C3047: =TEXT(A3047,"MMM-YYYY") | D3047: =INT(A3047)-WEEKDAY(A3047,2)+1 | E3047: dchoudhury | F3047: 98223 | G3047: 4 | H3047: 14 | I3047: 2 minute(s) and 23 second(s) | J3047: =IFERROR(VALUE(TRIM(LEFT(I3047,FIND("minute",I3047)-1)))*60,0)+IFERROR(VALUE(SUBSTITUTE(MID(I3047,IFERROR(FIND("and",I3047)+3,1),20),"second(s)","")),0) | K3047: =J3047/60 | L3047: =IFERROR(J3047/H3047,"") | M3047: 2.5.12 | N3047: =IF(J3047>300,1,0) | O3047: =IF(J3047>600,1,0) | P3047: =IF(H3047>0,J3047,"") | Q3047: =TEXT(A3047,"YYYY-MM-DD HH") | R3047: =COUNTIF($Q$2:$Q$5295,Q3047) | S3047: =IF(R3047<=2,"1-2",IF(R3047<=5,"3-5",IF(R3047<=10,"6-10","11+")))
A3048: 46195.949 | B3048: =TEXT(A3048,"YYYY-MM") | C3048: =TEXT(A3048,"MMM-YYYY") | D3048: =INT(A3048)-WEEKDAY(A3048,2)+1 | E3048: ssarkar | F3048: 117664 | G3048: 3 | H3048: 11 | I3048: 5 minute(s) and 57 second(s) | J3048: =IFERROR(VALUE(TRIM(LEFT(I3048,FIND("minute",I3048)-1)))*60,0)+IFERROR(VALUE(SUBSTITUTE(MID(I3048,IFERROR(FIND("and",I3048)+3,1),20),"second(s)","")),0) | K3048: =J3048/60 | L3048: =IFERROR(J3048/H3048,"") | M3048: 2.5.12 | N3048: =IF(J3048>300,1,0) | O3048: =IF(J3048>600,1,0) | P3048: =IF(H3048>0,J3048,"") | Q3048: =TEXT(A3048,"YYYY-MM-DD HH") | R3048: =COUNTIF($Q$2:$Q$5295,Q3048) | S3048: =IF(R3048<=2,"1-2",IF(R3048<=5,"3-5",IF(R3048<=10,"6-10","11+")))
A3049: 46195.967 | B3049: =TEXT(A3049,"YYYY-MM") | C3049: =TEXT(A3049,"MMM-YYYY") | D3049: =INT(A3049)-WEEKDAY(A3049,2)+1 | E3049: ssaha | F3049: 125435 | G3049: 4 | H3049: 8 | I3049: 1 minute(s) and 34 second(s) | J3049: =IFERROR(VALUE(TRIM(LEFT(I3049,FIND("minute",I3049)-1)))*60,0)+IFERROR(VALUE(SUBSTITUTE(MID(I3049,IFERROR(FIND("and",I3049)+3,1),20),"second(s)","")),0) | K3049: =J3049/60 | L3049: =IFERROR(J3049/H3049,"") | M3049: 2.5.12 | N3049: =IF(J3049>300,1,0) | O3049: =IF(J3049>600,1,0) | P3049: =IF(H3049>0,J3049,"") | Q3049: =TEXT(A3049,"YYYY-MM-DD HH") | R3049: =COUNTIF($Q$2:$Q$5295,Q3049) | S3049: =IF(R3049<=2,"1-2",IF(R3049<=5,"3-5",IF(R3049<=10,"6-10","11+")))
A3050: 46195.986 | B3050: =TEXT(A3050,"YYYY-MM") | C3050: =TEXT(A3050,"MMM-YYYY") | D3050: =INT(A3050)-WEEKDAY(A3050,2)+1 | E3050: mgupta | F3050: 109844 | G3050: 4 | H3050: 20 | I3050: 7 minute(s) and 54 second(s) | J3050: =IFERROR(VALUE(TRIM(LEFT(I3050,FIND("minute",I3050)-1)))*60,0)+IFERROR(VALUE(SUBSTITUTE(MID(I3050,IFERROR(FIND("and",I3050)+3,1),20),"second(s)","")),0) | K3050: =J3050/60 | L3050: =IFERROR(J3050/H3050,"") | M3050: 2.5.12 | N3050: =IF(J3050>300,1,0) | O3050: =IF(J3050>600,1,0) | P3050: =IF(H3050>0,J3050,"") | Q3050: =TEXT(A3050,"YYYY-MM-DD HH") | R3050: =COUNTIF($Q$2:$Q$5295,Q3050) | S3050: =IF(R3050<=2,"1-2",IF(R3050<=5,"3-5",IF(R3050<=10,"6-10","11+")))
A3051: 46196.066 | B3051: =TEXT(A3051,"YYYY-MM") | C3051: =TEXT(A3051,"MMM-YYYY") | D3051: =INT(A3051)-WEEKDAY(A3051,2)+1 | E3051: shassan | F3051: 121937 | G3051: 4 | H3051: 14 | I3051: 3 minute(s) and 35 second(s) | J3051: =IFERROR(VALUE(TRIM(LEFT(I3051,FIND("minute",I3051)-1)))*60,0)+IFERROR(VALUE(SUBSTITUTE(MID(I3051,IFERROR(FIND("and",I3051)+3,1),20),"second(s)","")),0) | K3051: =J3051/60 | L3051: =IFERROR(J3051/H3051,"") | M3051: 2.5.12 | N3051: =IF(J3051>300,1,0) | O3051: =IF(J3051>600,1,0) | P3051: =IF(H3051>0,J3051,"") | Q3051: =TEXT(A3051,"YYYY-MM-DD HH") | R3051: =COUNTIF($Q$2:$Q$5295,Q3051) | S3051: =IF(R3051<=2,"1-2",IF(R3051<=5,"3-5",IF(R3051<=10,"6-10","11+")))
A3052: 46196.09 | B3052: =TEXT(A3052,"YYYY-MM") | C3052: =TEXT(A3052,"MMM-YYYY") | D3052: =INT(A3052)-WEEKDAY(A3052,2)+1 | E3052: mgupta | F3052: 122509 | G3052: 4 | H3052: 14 | I3052: 3 minute(s) and 47 second(s) | J3052: =IFERROR(VALUE(TRIM(LEFT(I3052,FIND("minute",I3052)-1)))*60,0)+IFERROR(VALUE(SUBSTITUTE(MID(I3052,IFERROR(FIND("and",I3052)+3,1),20),"second(s)","")),0) | K3052: =J3052/60 | L3052: =IFERROR(J3052/H3052,"") | M3052: 2.5.12 | N3052: =IF(J3052>300,1,0) | O3052: =IF(J3052>600,1,0) | P3052: =IF(H3052>0,J3052,"") | Q3052: =TEXT(A3052,"YYYY-MM-DD HH") | R3052: =COUNTIF($Q$2:$Q$5295,Q3052) | S3052: =IF(R3052<=2,"1-2",IF(R3052<=5,"3-5",IF(R3052<=10,"6-10","11+")))
A3053: 46196.091 | B3053: =TEXT(A3053,"YYYY-MM") | C3053: =TEXT(A3053,"MMM-YYYY") | D3053: =INT(A3053)-WEEKDAY(A3053,2)+1 | E3053: sthomas | F3053: 113240 | G3053: 3 | H3053: 19 | I3053: 4 minute(s) and 47 second(s) | J3053: =IFERROR(VALUE(TRIM(LEFT(I3053,FIND("minute",I3053)-1)))*60,0)+IFERROR(VALUE(SUBSTITUTE(MID(I3053,IFERROR(FIND("and",I3053)+3,1),20),"second(s)","")),0) | K3053: =J3053/60 | L3053: =IFERROR(J3053/H3053,"") | M3053: 2.5.12 | N3053: =IF(J3053>300,1,0) | O3053: =IF(J3053>600,1,0) | P3053: =IF(H3053>0,J3053,"") | Q3053: =TEXT(A3053,"YYYY-MM-DD HH") | R3053: =COUNTIF($Q$2:$Q$5295,Q3053) | S3053: =IF(R3053<=2,"1-2",IF(R3053<=5,"3-5",IF(R3053<=10,"6-10","11+")))
